Workbook

Sheet Sheet1
B1: size_go | J1: uuid
A2: file_type | B2: audio | C2: autre | D2: jpeg | E2: ocr xml | F2: pdf | G2: tiff | H2: video | I2: Total | J2: audio | K2: autre | L2: jpeg | M2: ocr xml | N2: pdf | O2: tiff | P2: video | Q2: Total | R2: Q | S2: jpeg_compresse_Go | T2: jpeg_natif_Go | U2: alto_Go | V2: ratio_audio | W2: audio_diffusion_Go | X2: ratio_video | Y2: video_diffusion_Go | Z2: poids_final_Go
A3: corpus_code
A4: AMR_AFF | G4: 119.75894 | I4: 119.75894 | O4: 1005 | Q4: 1005 | R4: 85 | S4: =IF(OR(N(G4)=0,$R4=""),"",IFERROR(G4/INDEX(Ratios!$B$2:$F$79,MATCH($A4,Ratios!$A$2:$A$79,0),MATCH($R4,Ratios!$B$1:$F$1,0)),"ratio inconnu")) -> 7.6022943 | T4: =IF(N(D4)>0,D4,"") | U4: =IF(N(E4)>0,E4,"") | W4: =IF(N(B4)=0,"",IFERROR(B4/V4,"")) | Y4: =IF(N(H4)=0,"",IFERROR(H4/X4,"")) | Z4: =N(C4)+N(F4)+N(T4)+N(U4)+N(S4)+N(W4)+N(Y4) -> 7.6022943
A5: AMR_CAD | D5: 4.8604358 | F5: 0.10108175 | G5: 9.7903723 | I5: 14.75189 | L5: 193 | N5: 29 | O5: 25 | Q5: 247 | R5: 85 | S5: =IF(OR(N(G5)=0,$R5=""),"",IFERROR(G5/INDEX(Ratios!$B$2:$F$79,MATCH($A5,Ratios!$A$2:$A$79,0),MATCH($R5,Ratios!$B$1:$F$1,0)),"ratio inconnu")) -> 0.70903623 | T5: =IF(N(D5)>0,D5,"") -> 4.8604358 | U5: =IF(N(E5)>0,E5,"") | W5: =IF(N(B5)=0,"",IFERROR(B5/V5,"")) | Y5: =IF(N(H5)=0,"",IFERROR(H5/X5,"")) | Z5: =N(C5)+N(F5)+N(T5)+N(U5)+N(S5)+N(W5)+N(Y5) -> 5.6705538
A6: AMR_DEL | E6: 12.18667 | G6: 2143.7979 | I6: 2155.9846 | M6: 54734 | O6: 67364 | Q6: 122098 | R6: 85 | S6: =IF(OR(N(G6)=0,$R6=""),"",IFERROR(G6/INDEX(Ratios!$B$2:$F$79,MATCH($A6,Ratios!$A$2:$A$79,0),MATCH($R6,Ratios!$B$1:$F$1,0)),"ratio inconnu")) -> 182.00169 | T6: =IF(N(D6)>0,D6,"") | U6: =IF(N(E6)>0,E6,"") -> 12.18667 | W6: =IF(N(B6)=0,"",IFERROR(B6/V6,"")) | Y6: =IF(N(H6)=0,"",IFERROR(H6/X6,"")) | Z6: =N(C6)+N(F6)+N(T6)+N(U6)+N(S6)+N(W6)+N(Y6) -> 194.18836
A7: AMR_GUE | D7: 1.6264555 | E7: 0.0347023 | I7: 1.6611578 | L7: 339 | M7: 339 | Q7: 678 | S7: =IF(OR(N(G7)=0,$R7=""),"",IFERROR(G7/INDEX(Ratios!$B$2:$F$79,MATCH($A7,Ratios!$A$2:$A$79,0),MATCH($R7,Ratios!$B$1:$F$1,0)),"ratio inconnu")) | T7: =IF(N(D7)>0,D7,"") -> 1.6264555 | U7: =IF(N(E7)>0,E7,"") -> 0.0347023 | W7: =IF(N(B7)=0,"",IFERROR(B7/V7,"")) | Y7: =IF(N(H7)=0,"",IFERROR(H7/X7,"")) | Z7: =N(C7)+N(F7)+N(T7)+N(U7)+N(S7)+N(W7)+N(Y7) -> 1.6611578
A8: AMR_OBJ | G8: 0.3984854 | I8: 0.3984854 | O8: 99 | Q8: 99 | R8: 85 | S8: =IF(OR(N(G8)=0,$R8=""),"",IFERROR(G8/INDEX(Ratios!$B$2:$F$79,MATCH($A8,Ratios!$A$2:$A$79,0),MATCH($R8,Ratios!$B$1:$F$1,0)),"ratio inconnu")) -> 0.014339681 | T8: =IF(N(D8)>0,D8,"") | U8: =IF(N(E8)>0,E8,"") | W8: =IF(N(B8)=0,"",IFERROR(B8/V8,"")) | Y8: =IF(N(H8)=0,"",IFERROR(H8/X8,"")) | Z8: =N(C8)+N(F8)+N(T8)+N(U8)+N(S8)+N(W8)+N(Y8) -> 0.014339681
A9: AMR_PHO | G9: 7.5648264 | I9: 7.5648264 | O9: 1194 | Q9: 1194 | R9: 85 | S9: =IF(OR(N(G9)=0,$R9=""),"",IFERROR(G9/INDEX(Ratios!$B$2:$F$79,MATCH($A9,Ratios!$A$2:$A$79,0),MATCH($R9,Ratios!$B$1:$F$1,0)),"ratio inconnu")) -> 0.33109359 | T9: =IF(N(D9)>0,D9,"") | U9: =IF(N(E9)>0,E9,"") | W9: =IF(N(B9)=0,"",IFERROR(B9/V9,"")) | Y9: =IF(N(H9)=0,"",IFERROR(H9/X9,"")) | Z9: =N(C9)+N(F9)+N(T9)+N(U9)+N(S9)+N(W9)+N(Y9) -> 0.33109359
A10: AMR_PLA | D10: 2.9645272 | G10: 1.1646301 | I10: 4.1291573 | L10: 115 | O10: 11 | Q10: 126 | R10: 85 | S10: =IF(OR(N(G10)=0,$R10=""),"",IFERROR(G10/INDEX(Ratios!$B$2:$F$79,MATCH($A10,Ratios!$A$2:$A$79,0),MATCH($R10,Ratios!$B$1:$F$1,0)),"ratio inconnu")) -> ratio inconnu | T10: =IF(N(D10)>0,D10,"") -> 2.9645272 | U10: =IF(N(E10)>0,E10,"") | W10: =IF(N(B10)=0,"",IFERROR(B10/V10,"")) | Y10: =IF(N(H10)=0,"",IFERROR(H10/X10,"")) | Z10: =N(C10)+N(F10)+N(T10)+N(U10)+N(S10)+N(W10)+N(Y10) -> 2.9645272
A11: AMR_POP | D11: 78.301166 | G11: 0.12254153 | I11: 78.423707 | L11: 65099 | O11: 8 | Q11: 65107 | R11: 85 | S11: =IF(OR(N(G11)=0,$R11=""),"",IFERROR(G11/INDEX(Ratios!$B$2:$F$79,MATCH($A11,Ratios!$A$2:$A$79,0),MATCH($R11,Ratios!$B$1:$F$1,0)),"ratio inconnu")) -> 0.0070808694 | T11: =IF(N(D11)>0,D11,"") -> 78.301166 | U11: =IF(N(E11)>0,E11,"") | W11: =IF(N(B11)=0,"",IFERROR(B11/V11,"")) | Y11: =IF(N(H11)=0,"",IFERROR(H11/X11,"")) | Z11: =N(C11)+N(F11)+N(T11)+N(U11)+N(S11)+N(W11)+N(Y11) -> 78.308246
A12: AMR_PR | D12: 7.8488656 | G12: 60.365706 | I12: 68.214571 | L12: 162 | O12: 506 | Q12: 668 | R12: 85 | S12: =IF(OR(N(G12)=0,$R12=""),"",IFERROR(G12/INDEX(Ratios!$B$2:$F$79,MATCH($A12,Ratios!$A$2:$A$79,0),MATCH($R12,Ratios!$B$1:$F$1,0)),"ratio inconnu")) -> 3.9745658 | T12: =IF(N(D12)>0,D12,"") -> 7.8488656 | U12: =IF(N(E12)>0,E12,"") | W12: =IF(N(B12)=0,"",IFERROR(B12/V12,"")) | Y12: =IF(N(H12)=0,"",IFERROR(H12/X12,"")) | Z12: =N(C12)+N(F12)+N(T12)+N(U12)+N(S12)+N(W12)+N(Y12) -> 11.823431
A13: AMR_RAM | E13: 2.2642444 | G13: 412.46979 | I13: 414.73403 | M13: 18409 | O13: 18408 | Q13: 36817 | R13: 85 | S13: =IF(OR(N(G13)=0,$R13=""),"",IFERROR(G13/INDEX(Ratios!$B$2:$F$79,MATCH($A13,Ratios!$A$2:$A$79,0),MATCH($R13,Ratios!$B$1:$F$1,0)),"ratio inconnu")) -> 31.826373 | T13: =IF(N(D13)>0,D13,"") | U13: =IF(N(E13)>0,E13,"") -> 2.2642444 | W13: =IF(N(B13)=0,"",IFERROR(B13/V13,"")) | Y13: =IF(N(H13)=0,"",IFERROR(H13/X13,"")) | Z13: =N(C13)+N(F13)+N(T13)+N(U13)+N(S13)+N(W13)+N(Y13) -> 34.090617
A14: ARA_CPS | B14: 0.7602931 | D14: 0.31573411 | I14: 1.0760272 | J14: 76 | L14: 70 | Q14: 146 | S14: =IF(OR(N(G14)=0,$R14=""),"",IFERROR(G14/INDEX(Ratios!$B$2:$F$79,MATCH($A14,Ratios!$A$2:$A$79,0),MATCH($R14,Ratios!$B$1:$F$1,0)),"ratio inconnu")) | T14: =IF(N(D14)>0,D14,"") -> 0.31573411 | U14: =IF(N(E14)>0,E14,"") | V14: 7 | W14: =IF(N(B14)=0,"",IFERROR(B14/V14,"")) -> 0.1086133 | Y14: =IF(N(H14)=0,"",IFERROR(H14/X14,"")) | Z14: =N(C14)+N(F14)+N(T14)+N(U14)+N(S14)+N(W14)+N(Y14) -> 0.42434741
A15: CSV_PAL | G15: 6.1954354 | I15: 6.1954354 | O15: 242 | Q15: 242 | R15: 85 | S15: =IF(OR(N(G15)=0,$R15=""),"",IFERROR(G15/INDEX(Ratios!$B$2:$F$79,MATCH($A15,Ratios!$A$2:$A$79,0),MATCH($R15,Ratios!$B$1:$F$1,0)),"ratio inconnu")) -> 0.32335258 | T15: =IF(N(D15)>0,D15,"") | U15: =IF(N(E15)>0,E15,"") | W15: =IF(N(B15)=0,"",IFERROR(B15/V15,"")) | Y15: =IF(N(H15)=0,"",IFERROR(H15/X15,"")) | Z15: =N(C15)+N(F15)+N(T15)+N(U15)+N(S15)+N(W15)+N(Y15) -> 0.32335258
A16: LAI | G16: 30.324552 | I16: 30.324552 | O16: 1145 | Q16: 1145 | R16: 85 | S16: =IF(OR(N(G16)=0,$R16=""),"",IFERROR(G16/INDEX(Ratios!$B$2:$F$79,MATCH($A16,Ratios!$A$2:$A$79,0),MATCH($R16,Ratios!$B$1:$F$1,0)),"ratio inconnu")) -> 1.7111247 | T16: =IF(N(D16)>0,D16,"") | U16: =IF(N(E16)>0,E16,"") | W16: =IF(N(B16)=0,"",IFERROR(B16/V16,"")) | Y16: =IF(N(H16)=0,"",IFERROR(H16/X16,"")) | Z16: =N(C16)+N(F16)+N(T16)+N(U16)+N(S16)+N(W16)+N(Y16) -> 1.7111247
A17: LAR_PUB | G17: 17.070333 | I17: 17.070333 | O17: 3811 | Q17: 3811 | R17: 85 | S17: =IF(OR(N(G17)=0,$R17=""),"",IFERROR(G17/INDEX(Ratios!$B$2:$F$79,MATCH($A17,Ratios!$A$2:$A$79,0),MATCH($R17,Ratios!$B$1:$F$1,0)),"ratio inconnu")) -> 12.560951 | T17: =IF(N(D17)>0,D17,"") | U17: =IF(N(E17)>0,E17,"") | W17: =IF(N(B17)=0,"",IFERROR(B17/V17,"")) | Y17: =IF(N(H17)=0,"",IFERROR(H17/X17,"")) | Z17: =N(C17)+N(F17)+N(T17)+N(U17)+N(S17)+N(W17)+N(Y17) -> 12.560951
A18: MDF_MTX | H18: 67.735698 | I18: 67.735698 | P18: 17 | Q18: 17 | S18: =IF(OR(N(G18)=0,$R18=""),"",IFERROR(G18/INDEX(Ratios!$B$2:$F$79,MATCH($A18,Ratios!$A$2:$A$79,0),MATCH($R18,Ratios!$B$1:$F$1,0)),"ratio inconnu")) | T18: =IF(N(D18)>0,D18,"") | U18: =IF(N(E18)>0,E18,"") | W18: =IF(N(B18)=0,"",IFERROR(B18/V18,"")) | X18: 20 | Y18: =IF(N(H18)=0,"",IFERROR(H18/X18,"")) -> 3.3867849 | Z18: =N(C18)+N(F18)+N(T18)+N(U18)+N(S18)+N(W18)+N(Y18) -> 3.3867849
A19: MED_AFF | G19: 293.77439 | I19: 293.77439 | O19: 4147 | Q19: 4147 | R19: 85 | S19: =IF(OR(N(G19)=0,$R19=""),"",IFERROR(G19/INDEX(Ratios!$B$2:$F$79,MATCH($A19,Ratios!$A$2:$A$79,0),MATCH($R19,Ratios!$B$1:$F$1,0)),"ratio inconnu")) -> 24.155105 | T19: =IF(N(D19)>0,D19,"") | U19: =IF(N(E19)>0,E19,"") | W19: =IF(N(B19)=0,"",IFERROR(B19/V19,"")) | Y19: =IF(N(H19)=0,"",IFERROR(H19/X19,"")) | Z19: =N(C19)+N(F19)+N(T19)+N(U19)+N(S19)+N(W19)+N(Y19) -> 24.155105
A20: MED_CHA | G20: 8.1566307 | I20: 8.1566307 | O20: 360 | Q20: 360 | R20: 85 | S20: =IF(OR(N(G20)=0,$R20=""),"",IFERROR(G20/INDEX(Ratios!$B$2:$F$79,MATCH($A20,Ratios!$A$2:$A$79,0),MATCH($R20,Ratios!$B$1:$F$1,0)),"ratio inconnu")) -> 0.60865836 | T20: =IF(N(D20)>0,D20,"") | U20: =IF(N(E20)>0,E20,"") | W20: =IF(N(B20)=0,"",IFERROR(B20/V20,"")) | Y20: =IF(N(H20)=0,"",IFERROR(H20/X20,"")) | Z20: =N(C20)+N(F20)+N(T20)+N(U20)+N(S20)+N(W20)+N(Y20) -> 0.60865836
A21: MED_CP | D21: 0.12359426 | G21: 25.336349 | I21: 25.459943 | L21: 174 | O21: 4489 | Q21: 4663 | R21: 85 | S21: =IF(OR(N(G21)=0,$R21=""),"",IFERROR(G21/INDEX(Ratios!$B$2:$F$79,MATCH($A21,Ratios!$A$2:$A$79,0),MATCH($R21,Ratios!$B$1:$F$1,0)),"ratio inconnu")) -> 1.780989 | T21: =IF(N(D21)>0,D21,"") -> 0.12359426 | U21: =IF(N(E21)>0,E21,"") | W21: =IF(N(B21)=0,"",IFERROR(B21/V21,"")) | Y21: =IF(N(H21)=0,"",IFERROR(H21/X21,"")) | Z21: =N(C21)+N(F21)+N(T21)+N(U21)+N(S21)+N(W21)+N(Y21) -> 1.9045832
A22: MED_EPH | G22: 9.3654013 | I22: 9.3654013 | O22: 840 | Q22: 840 | R22: 85 | S22: =IF(OR(N(G22)=0,$R22=""),"",IFERROR(G22/INDEX(Ratios!$B$2:$F$79,MATCH($A22,Ratios!$A$2:$A$79,0),MATCH($R22,Ratios!$B$1:$F$1,0)),"ratio inconnu")) -> 0.42870097 | T22: =IF(N(D22)>0,D22,"") | U22: =IF(N(E22)>0,E22,"") | W22: =IF(N(B22)=0,"",IFERROR(B22/V22,"")) | Y22: =IF(N(H22)=0,"",IFERROR(H22/X22,"")) | Z22: =N(C22)+N(F22)+N(T22)+N(U22)+N(S22)+N(W22)+N(Y22) -> 0.42870097
A23: MED_FLR | G23: 0.035761926 | I23: 0.035761926 | O23: 1 | Q23: 1 | R23: 85 | S23: =IF(OR(N(G23)=0,$R23=""),"",IFERROR(G23/INDEX(Ratios!$B$2:$F$79,MATCH($A23,Ratios!$A$2:$A$79,0),MATCH($R23,Ratios!$B$1:$F$1,0)),"ratio inconnu")) -> 0.0017967206 | T23: =IF(N(D23)>0,D23,"") | U23: =IF(N(E23)>0,E23,"") | W23: =IF(N(B23)=0,"",IFERROR(B23/V23,"")) | Y23: =IF(N(H23)=0,"",IFERROR(H23/X23,"")) | Z23: =N(C23)+N(F23)+N(T23)+N(U23)+N(S23)+N(W23)+N(Y23) -> 0.0017967206
A24: MED_FOO | B24: 0.14379284 | D24: 0.0035088435 | I24: 0.14730168 | J24: 3 | L24: 3 | Q24: 6 | S24: =IF(OR(N(G24)=0,$R24=""),"",IFERROR(G24/INDEX(Ratios!$B$2:$F$79,MATCH($A24,Ratios!$A$2:$A$79,0),MATCH($R24,Ratios!$B$1:$F$1,0)),"ratio inconnu")) | T24: =IF(N(D24)>0,D24,"") -> 0.0035088435 | U24: =IF(N(E24)>0,E24,"") | V24: 7 | W24: =IF(N(B24)=0,"",IFERROR(B24/V24,"")) -> 0.020541834 | Y24: =IF(N(H24)=0,"",IFERROR(H24/X24,"")) | Z24: =N(C24)+N(F24)+N(T24)+N(U24)+N(S24)+N(W24)+N(Y24) -> 0.024050678
A25: MED_IMA | D25: 0.51905306 | G25: 68.252009 | I25: 68.771062 | L25: 180 | O25: 5593 | Q25: 5773 | R25: 85 | S25: =IF(OR(N(G25)=0,$R25=""),"",IFERROR(G25/INDEX(Ratios!$B$2:$F$79,MATCH($A25,Ratios!$A$2:$A$79,0),MATCH($R25,Ratios!$B$1:$F$1,0)),"ratio inconnu")) -> 7.3674448 | T25: =IF(N(D25)>0,D25,"") -> 0.51905306 | U25: =IF(N(E25)>0,E25,"") | W25: =IF(N(B25)=0,"",IFERROR(B25/V25,"")) | Y25: =IF(N(H25)=0,"",IFERROR(H25/X25,"")) | Z25: =N(C25)+N(F25)+N(T25)+N(U25)+N(S25)+N(W25)+N(Y25) -> 7.8864979
A26: MED_LET | G26: 11.058136 | I26: 11.058136 | O26: 559 | Q26: 559 | R26: 85 | S26: =IF(OR(N(G26)=0,$R26=""),"",IFERROR(G26/INDEX(Ratios!$B$2:$F$79,MATCH($A26,Ratios!$A$2:$A$79,0),MATCH($R26,Ratios!$B$1:$F$1,0)),"ratio inconnu")) -> 0.96007436 | T26: =IF(N(D26)>0,D26,"") | U26: =IF(N(E26)>0,E26,"") | W26: =IF(N(B26)=0,"",IFERROR(B26/V26,"")) | Y26: =IF(N(H26)=0,"",IFERROR(H26/X26,"")) | Z26: =N(C26)+N(F26)+N(T26)+N(U26)+N(S26)+N(W26)+N(Y26) -> 0.96007436
A27: MED_MAR | G27: 3.4246863 | I27: 3.4246863 | O27: 62 | Q27: 62 | R27: 85 | S27: =IF(OR(N(G27)=0,$R27=""),"",IFERROR(G27/INDEX(Ratios!$B$2:$F$79,MATCH($A27,Ratios!$A$2:$A$79,0),MATCH($R27,Ratios!$B$1:$F$1,0)),"ratio inconnu")) -> 0.27833926 | T27: =IF(N(D27)>0,D27,"") | U27: =IF(N(E27)>0,E27,"") | W27: =IF(N(B27)=0,"",IFERROR(B27/V27,"")) | Y27: =IF(N(H27)=0,"",IFERROR(H27/X27,"")) | Z27: =N(C27)+N(F27)+N(T27)+N(U27)+N(S27)+N(W27)+N(Y27) -> 0.27833926
A28: MED_MON | G28: 51.960805 | I28: 51.960805 | O28: 1384 | Q28: 1384 | R28: 85 | S28: =IF(OR(N(G28)=0,$R28=""),"",IFERROR(G28/INDEX(Ratios!$B$2:$F$79,MATCH($A28,Ratios!$A$2:$A$79,0),MATCH($R28,Ratios!$B$1:$F$1,0)),"ratio inconnu")) -> 3.2197797 | T28: =IF(N(D28)>0,D28,"") | U28: =IF(N(E28)>0,E28,"") | W28: =IF(N(B28)=0,"",IFERROR(B28/V28,"")) | Y28: =IF(N(H28)=0,"",IFERROR(H28/X28,"")) | Z28: =N(C28)+N(F28)+N(T28)+N(U28)+N(S28)+N(W28)+N(Y28) -> 3.2197797
A29: MED_MS | D29: 0.22576554 | G29: 959.48758 | I29: 959.71335 | L29: 248 | O29: 33054 | Q29: 33302 | R29: 85 | S29: =IF(OR(N(G29)=0,$R29=""),"",IFERROR(G29/INDEX(Ratios!$B$2:$F$79,MATCH($A29,Ratios!$A$2:$A$79,0),MATCH($R29,Ratios!$B$1:$F$1,0)),"ratio inconnu")) -> 75.884813 | T29: =IF(N(D29)>0,D29,"") -> 0.22576554 | U29: =IF(N(E29)>0,E29,"") | W29: =IF(N(B29)=0,"",IFERROR(B29/V29,"")) | Y29: =IF(N(H29)=0,"",IFERROR(H29/X29,"")) | Z29: =N(C29)+N(F29)+N(T29)+N(U29)+N(S29)+N(W29)+N(Y29) -> 76.110579
A30: MED_PAR | C30: 0.0019432362 | D30: 4.9039416 | G30: 446.97354 | I30: 451.87943 | K30: 2 | L30: 4414 | O30: 16299 | Q30: 20715 | R30: 85 | S30: =IF(OR(N(G30)=0,$R30=""),"",IFERROR(G30/INDEX(Ratios!$B$2:$F$79,MATCH($A30,Ratios!$A$2:$A$79,0),MATCH($R30,Ratios!$B$1:$F$1,0)),"ratio inconnu")) -> 26.017086 | T30: =IF(N(D30)>0,D30,"") -> 4.9039416 | U30: =IF(N(E30)>0,E30,"") | W30: =IF(N(B30)=0,"",IFERROR(B30/V30,"")) | Y30: =IF(N(H30)=0,"",IFERROR(H30/X30,"")) | Z30: =N(C30)+N(F30)+N(T30)+N(U30)+N(S30)+N(W30)+N(Y30) -> 30.922971
A31: MED_PHO | C31: 0.011707176 | D31: 4.0489851 | G31: 16.565632 | I31: 20.626324 | K31: 1 | L31: 274 | O31: 865 | Q31: 1140 | R31: 85 | S31: =IF(OR(N(G31)=0,$R31=""),"",IFERROR(G31/INDEX(Ratios!$B$2:$F$79,MATCH($A31,Ratios!$A$2:$A$79,0),MATCH($R31,Ratios!$B$1:$F$1,0)),"ratio inconnu")) -> 0.67002232 | T31: =IF(N(D31)>0,D31,"") -> 4.0489851 | U31: =IF(N(E31)>0,E31,"") | W31: =IF(N(B31)=0,"",IFERROR(B31/V31,"")) | Y31: =IF(N(H31)=0,"",IFERROR(H31/X31,"")) | Z31: =N(C31)+N(F31)+N(T31)+N(U31)+N(S31)+N(W31)+N(Y31) -> 4.7307146
A32: MED_PLA | G32: 31.469768 | I32: 31.469768 | O32: 271 | Q32: 271 | R32: 85 | S32: =IF(OR(N(G32)=0,$R32=""),"",IFERROR(G32/INDEX(Ratios!$B$2:$F$79,MATCH($A32,Ratios!$A$2:$A$79,0),MATCH($R32,Ratios!$B$1:$F$1,0)),"ratio inconnu")) -> 2.5139614 | T32: =IF(N(D32)>0,D32,"") | U32: =IF(N(E32)>0,E32,"") | W32: =IF(N(B32)=0,"",IFERROR(B32/V32,"")) | Y32: =IF(N(H32)=0,"",IFERROR(H32/X32,"")) | Z32: =N(C32)+N(F32)+N(T32)+N(U32)+N(S32)+N(W32)+N(Y32) -> 2.5139614
A33: MED_PUB | G33: 46.526942 | I33: 46.526942 | O33: 2419 | Q33: 2419 | R33: 85 | S33: =IF(OR(N(G33)=0,$R33=""),"",IFERROR(G33/INDEX(Ratios!$B$2:$F$79,MATCH($A33,Ratios!$A$2:$A$79,0),MATCH($R33,Ratios!$B$1:$F$1,0)),"ratio inconnu")) -> 2.6629431 | T33: =IF(N(D33)>0,D33,"") | U33: =IF(N(E33)>0,E33,"") | W33: =IF(N(B33)=0,"",IFERROR(B33/V33,"")) | Y33: =IF(N(H33)=0,"",IFERROR(H33/X33,"")) | Z33: =N(C33)+N(F33)+N(T33)+N(U33)+N(S33)+N(W33)+N(Y33) -> 2.6629431
A34: MED_VDM | G34: 747.33292 | I34: 747.33292 | O34: 31272 | Q34: 31272 | R34: 85 | S34: =IF(OR(N(G34)=0,$R34=""),"",IFERROR(G34/INDEX(Ratios!$B$2:$F$79,MATCH($A34,Ratios!$A$2:$A$79,0),MATCH($R34,Ratios!$B$1:$F$1,0)),"ratio inconnu")) -> 41.92611 | T34: =IF(N(D34)>0,D34,"") | U34: =IF(N(E34)>0,E34,"") | W34: =IF(N(B34)=0,"",IFERROR(B34/V34,"")) | Y34: =IF(N(H34)=0,"",IFERROR(H34/X34,"")) | Z34: =N(C34)+N(F34)+N(T34)+N(U34)+N(S34)+N(W34)+N(Y34) -> 41.92611
A35: MUS_ARC | D35: 0.25753795 | G35: 1.1687228 | I35: 1.4262607 | L35: 95 | O35: 39 | Q35: 134 | R35: 85 | S35: =IF(OR(N(G35)=0,$R35=""),"",IFERROR(G35/INDEX(Ratios!$B$2:$F$79,MATCH($A35,Ratios!$A$2:$A$79,0),MATCH($R35,Ratios!$B$1:$F$1,0)),"ratio inconnu")) -> 0.060700259 | T35: =IF(N(D35)>0,D35,"") -> 0.25753795 | U35: =IF(N(E35)>0,E35,"") | W35: =IF(N(B35)=0,"",IFERROR(B35/V35,"")) | Y35: =IF(N(H35)=0,"",IFERROR(H35/X35,"")) | Z35: =N(C35)+N(F35)+N(T35)+N(U35)+N(S35)+N(W35)+N(Y35) -> 0.31823821
A36: MUS_VAI | D36: 2.1587492 | G36: 41.503363 | I36: 43.662112 | L36: 355 | O36: 1504 | Q36: 1859 | R36: 85 | S36: =IF(OR(N(G36)=0,$R36=""),"",IFERROR(G36/INDEX(Ratios!$B$2:$F$79,MATCH($A36,Ratios!$A$2:$A$79,0),MATCH($R36,Ratios!$B$1:$F$1,0)),"ratio inconnu")) -> 2.6281258 | T36: =IF(N(D36)>0,D36,"") -> 2.1587492 | U36: =IF(N(E36)>0,E36,"") | W36: =IF(N(B36)=0,"",IFERROR(B36/V36,"")) | Y36: =IF(N(H36)=0,"",IFERROR(H36/X36,"")) | Z36: =N(C36)+N(F36)+N(T36)+N(U36)+N(S36)+N(W36)+N(Y36) -> 4.7868751
A37: OBS_JOU | D37: 0.62891957 | F37: 0.56230454 | G37: 14.681884 | I37: 15.873108 | L37: 652 | N37: 31 | O37: 555 | Q37: 1238 | R37: 85 | S37: =IF(OR(N(G37)=0,$R37=""),"",IFERROR(G37/INDEX(Ratios!$B$2:$F$79,MATCH($A37,Ratios!$A$2:$A$79,0),MATCH($R37,Ratios!$B$1:$F$1,0)),"ratio inconnu")) -> 1.0502063 | T37: =IF(N(D37)>0,D37,"") -> 0.62891957 | U37: =IF(N(E37)>0,E37,"") | W37: =IF(N(B37)=0,"",IFERROR(B37/V37,"")) | Y37: =IF(N(H37)=0,"",IFERROR(H37/X37,"")) | Z37: =N(C37)+N(F37)+N(T37)+N(U37)+N(S37)+N(W37)+N(Y37) -> 2.2414304
A38: PRA_AVE | E38: 45.143753 | G38: 652.70601 | I38: 697.84976 | M38: 43519 | O38: 43991 | Q38: 87510 | R38: 85 | S38: =IF(OR(N(G38)=0,$R38=""),"",IFERROR(G38/INDEX(Ratios!$B$2:$F$79,MATCH($A38,Ratios!$A$2:$A$79,0),MATCH($R38,Ratios!$B$1:$F$1,0)),"ratio inconnu")) -> 143.76784 | T38: =IF(N(D38)>0,D38,"") | U38: =IF(N(E38)>0,E38,"") -> 45.143753 | W38: =IF(N(B38)=0,"",IFERROR(B38/V38,"")) | Y38: =IF(N(H38)=0,"",IFERROR(H38/X38,"")) | Z38: =N(C38)+N(F38)+N(T38)+N(U38)+N(S38)+N(W38)+N(Y38) -> 188.9116
A39: PRA_CRT | E39: 29.905321 | G39: 738.20475 | I39: 768.11007 | M39: 24225 | O39: 24227 | Q39: 48452 | R39: 85 | S39: =IF(OR(N(G39)=0,$R39=""),"",IFERROR(G39/INDEX(Ratios!$B$2:$F$79,MATCH($A39,Ratios!$A$2:$A$79,0),MATCH($R39,Ratios!$B$1:$F$1,0)),"ratio inconnu")) -> 126.08109 | T39: =IF(N(D39)>0,D39,"") | U39: =IF(N(E39)>0,E39,"") -> 29.905321 | W39: =IF(N(B39)=0,"",IFERROR(B39/V39,"")) | Y39: =IF(N(H39)=0,"",IFERROR(H39/X39,"")) | Z39: =N(C39)+N(F39)+N(T39)+N(U39)+N(S39)+N(W39)+N(Y39) -> 155.98641
A40: PRA_CTG | E40: 1.2715501 | G40: 40.659088 | I40: 41.930639 | M40: 1438 | O40: 1438 | Q40: 2876 | R40: 85 | S40: =IF(OR(N(G40)=0,$R40=""),"",IFERROR(G40/INDEX(Ratios!$B$2:$F$79,MATCH($A40,Ratios!$A$2:$A$79,0),MATCH($R40,Ratios!$B$1:$F$1,0)),"ratio inconnu")) -> 6.8037297 | T40: =IF(N(D40)>0,D40,"") | U40: =IF(N(E40)>0,E40,"") -> 1.2715501 | W40: =IF(N(B40)=0,"",IFERROR(B40/V40,"")) | Y40: =IF(N(H40)=0,"",IFERROR(H40/X40,"")) | Z40: =N(C40)+N(F40)+N(T40)+N(U40)+N(S40)+N(W40)+N(Y40) -> 8.0752798
...

Sheet Ratios
A1: corpus_code | B1: 75 | C1: 80 | D1: 85 | E1: 90 | F1: 95 | H1: qualites
A2: AMR_10FI | C2: 32.195 | D2: 26.514 | E2: 13.962 | F2: 9.108 | H2: 75
A3: AMR_1NumFi | C3: 45.523 | D3: 37.108 | E3: 19.95 | F3: 12.884 | H3: 80
A4: AMR_1PER3 | C4: 12.542 | D4: 10.493 | E4: 6.024 | F4: 3.787 | H4: 85
A5: AMR_21J | C5: 33.386 | D5: 27.094 | E5: 15.555 | F5: 10.073 | H5: 90
A6: AMR_2F | C6: 24.704 | D6: 20.965 | E6: 11.531 | F6: 7.842 | H6: 95
A7: AMR_310W | C7: 29.413 | D7: 24.45 | E7: 13.025 | F7: 8.349
A8: AMR_381W | C8: 29.904 | D8: 24.804 | E8: 13.587 | F8: 8.885
A9: AMR_3D | C9: 32.34 | D9: 26.373 | E9: 14.908 | F9: 9.62
A10: AMR_3FI | C10: 21.476 | D10: 17.858 | E10: 10.879 | F10: 5.874
A11: AMR_3O | C11: 16.748 | D11: 13.534 | E11: 7.325 | F11: 4.673
A12: AMR_3R | C12: 22.94 | D12: 19.114 | E12: 10.716 | F12: 7.174
A13: AMR_440W | C13: 30.193 | D13: 25.063 | E13: 13.68 | F13: 8.857
A14: AMR_4FI | C14: 17.404 | D14: 14.472 | E14: 8.959 | F14: 5.114
A15: AMR_4H | C15: 22.002 | D15: 18.109 | E15: 9.698 | F15: 6.411
A16: AMR_4M | C16: 10.454 | D16: 8.567 | E16: 4.514 | F16: 2.856
A17: AMR_500W | C17: 30.182 | D17: 24.792 | E17: 12.676 | F17: 8.256
A18: AMR_507W | C18: 29.723 | D18: 25.2 | E18: 13.657 | F18: 9.448
... A79: VAH_PUB | C79: 11.451 | D79: 9.732 | E79: 4.854 | F79: 3.31
